Workbook
Name Ставка: 1/5
Name Суммы: Данные!$C$2:$C$11

Sheet Данные
A1: Имя | B1: Отдел | C1: Сумма | D1: Дата | E1: Кол | F1: Флаг | G1: Смесь | H1: Текст | J1: Отдел | K1: Сумма | L1: Отдел
A2: Иван | B2: Продажи | C2: 1500 | D2: 46037 | E2: 3 | F2: TRUE | G2: 5 | H2: Привет мир | J2: Склад | K2: >500 | L2: Продажи
A3: Пётр | B3: Склад | C3: 230.5 | D3: 46081 | E3: 1 | F3: FALSE | G3: 12 | H3: abc | L3: Склад
A4: Мария | B4: Продажи | C4: 980 | D4: 46022 | E4: 7 | F4: TRUE | H4: ABC-123
A5: Анна | B5: Бухгалтерия | C5: 4200 | D5: 46082 | E5: 2 | F5: FALSE | G5: TRUE | H5: Иванов Иван Иванович
A6: Олег | B6: Склад | C6: 0 | D6: 45351 | E6: 5 | F6: TRUE | G6: =NA() -> #N/A | H6: a,b,c
A7: Иван | B7: Продажи | C7: 15.25 | D7: 46203 | E7: 8 | F7: FALSE | G7: 3.5 | H7: Москва
A8: Мария | B8: Бухгалтерия | C8: 3100 | D8: 46305 | E8: 1 | F8: TRUE | G8: ="" | H8: Сумма: 100
A9: Пётр | B9: Склад | C9: -200 | D9: 44927 | E9: 4 | F9: FALSE | G9: -2 | H9: x
A10: Анна | B10: Продажи | C10: 760 | D10: 46381 | E10: 6 | F10: TRUE | G10: текст | H10: Test
A11: Ольга | B11: Склад | C11: 1200 | D11: 46151 | E11: 2 | F11: FALSE | G11: 0 | H11: тест

Sheet Кв1
A1: 10
B2: 1

Sheet Кв2
A1: 20
B2: 2

Sheet Кв3
A1: 30
B2: 3

Sheet Формулы
A1: Группа | B1: Формула | C1: Excel
A2: Арифметика и операторы | B2: 1+2*3 | C2: =1+2*3 -> 7 | E2: =1+2*3
A3: Арифметика и операторы | B3: (1+2)*3 | C3: =(1+2)*3 -> 9 | E3: =(1+2)*3
A4: Арифметика и операторы | B4: 2^3^2 | C4: =2^3^2 -> 64 | E4: =2^3^2
A5: Арифметика и операторы | B5: -2^2 | C5: =-2^2 -> 4 | E5: =-2^2
A6: Арифметика и операторы | B6: 10/4 | C6: =10/4 -> 2.5 | E6: =10/4
A7: Арифметика и операторы | B7: 7/0 | C7: =7/0 -> #DIV/0! | E7: =7/0
A8: Арифметика и операторы | B8: 5% | C8: =5% -> 0.05 | E8: =5%
A9: Арифметика и операторы | B9: 50%*200 | C9: =50%*200 -> 100 | E9: =50%*200
A10: Арифметика и операторы | B10: "3"+4 | C10: ="3"+4 -> 7 | E10: ="3"+4
A11: Арифметика и операторы | B11: "abc"+1 | C11: ="abc"+1 -> #VALUE! | E11: ="abc"+1
A12: Арифметика и операторы | B12: "1,5"+1 | C12: ="1,5"+1 -> 2.5 | E12: ="1,5"+1
A13: Арифметика и операторы | B13: TRUE+TRUE | C13: =TRUE+TRUE -> 2 | E13: =ИСТИНА+ИСТИНА
A14: Арифметика и операторы | B14: 1=1 | C14: =1=1 -> TRUE | E14: =1=1
A15: Арифметика и операторы | B15: "a"="A" | C15: ="a"="A" -> TRUE | E15: ="a"="A"
A16: Арифметика и операторы | B16: "a"<"b" | C16: ="a"<"b" -> TRUE | E16: ="a"<"b"
A17: Арифметика и операторы | B17: "Б">"А" | C17: ="Б">"А" -> TRUE | E17: ="Б">"А"
A18: Арифметика и операторы | B18: 2<"1" | C18: =2<"1" -> TRUE | E18: =2<"1"
A19: Арифметика и операторы | B19: TRUE>1 | C19: =TRUE>1 -> TRUE | E19: =ИСТИНА>1
A20: Арифметика и операторы | B20: "x"&1.5 | C20: ="x"&1.5 -> x1,5 | E20: ="x"&1,5
A21: Арифметика и операторы | B21: 1&2 | C21: =1&2 -> 12 | E21: =1&2
A22: Арифметика и операторы | B22: ""&TRUE | C22: =""&TRUE -> ИСТИНА | E22: =""&ИСТИНА
A23: Арифметика и операторы | B23: 0.1+0.2 | C23: =0.1+0.2 -> 0.3 | E23: =0,1+0,2
A24: Арифметика и операторы | B24: 0.1+0.2=0.3 | C24: =0.1+0.2=0.3 -> TRUE | E24: =0,1+0,2=0,3
A25: Арифметика и операторы | B25: 1/3*3 | C25: =1/3*3 -> 1 | E25: =1/3*3
A26: Арифметика и операторы | B26: 10^-3 | C26: =10^-3 -> 0.001 | E26: =10^-3
A27: Арифметика и операторы | B27: 1E+3 | C27: =1000 -> 1000 | E27: =1000
A28: Арифметика и операторы | B28: 123456789012345678 | C28: =123456789012345000 -> 1.2345679e+17 | E28: =123456789012345000
A29: Арифметика и операторы | B29: 1/3 | C29: =1/3 -> 0.33333333 | E29: =1/3
A30: Арифметика и операторы | B30: 2/3+1000000 | C30: =2/3+1000000 -> 1000000.7 | E30: =2/3+1000000
A31: Арифметика и операторы | B31: Данные!C2+Данные!C3 | C31: =Данные!C2+Данные!C3 -> 1730.5 | E31: =Данные!C2+Данные!C3
A32: Арифметика и операторы | B32: Данные!G4+1 | C32: =Данные!G4+1 -> 1 | E32: =Данные!G4+1
A33: Арифметика и операторы | B33: Данные!G4&"x" | C33: =Данные!G4&"x" -> x | E33: =Данные!G4&"x"
A34: Арифметика и операторы | B34: Данные!G3*2 | C34: =Данные!G3*2 -> 24 | E34: =Данные!G3*2
A35: Арифметика и операторы | B35: Данные!G8+1 | C35: =Данные!G8+1 -> #VALUE! | E35: =Данные!G8+1
A36: Арифметика и операторы | B36: Данные!G6+1 | C36: =Данные!G6+1 -> #N/A | E36: =Данные!G6+1
A37: Математика | B37: SUM(Данные!C2:C11) | C37: =SUM(Данные!C2:C11) -> 11785.75 | E37: =СУММ(Данные!C2:C11)
A38: Математика | B38: SUM(Данные!G2:G11) | C38: =SUM(Данные!G2:G11) -> #N/A | E38: =СУММ(Данные!G2:G11)
A39: Математика | B39: SUM(1,"2",TRUE) | C39: =SUM(1,"2",TRUE) -> 4 | E39: =СУММ(1;"2";ИСТИНА)
A40: Математика | B40: SUM(Данные!C2:C11,100) | C40: =SUM(Данные!C2:C11,100) -> 11885.75 | E40: =СУММ(Данные!C2:C11;100)
...
